INFO     Test_Account_Delete_Class:Test_Acc_Delete.py:13 test_Account_Edit_011 is started 
INFO     Test_Account_Delete_Class:Test_Acc_Delete.py:15 opening the browser
INFO     Test_Account_Delete_Class:Test_Acc_Delete.py:17 Clicking on the login option
INFO     Test_Account_Delete_Class:Test_Acc_Delete.py:19 Entering the Username-->mragrendrata
INFO     Test_Account_Delete_Class:Test_Acc_Delete.py:21 Entering the password-->Mragren@123
INFO     Test_Account_Delete_Class:Test_Acc_Delete.py:23 Clicking on the login button
INFO     Test_Account_Delete_Class:Test_Acc_Delete.py:27 Clicking on Account management link
INFO     Test_Account_Delete_Class:Test_Acc_Delete.py:29 Entering the account id-->143
INFO     Test_Account_Delete_Class:Test_Acc_Delete.py:31 Clicking on the search account button
INFO     Test_Account_Delete_Class:Test_Acc_Delete.py:33 Clicking on the delete button
INFO     Test_Account_Delete_Class:Test_Acc_Delete.py:35 Validating account has been updated
INFO     Test_Account_Delete_Class:Test_Acc_Delete.py:42 test_Account_delete_011 is fail
WARNING  urllib3.connectionpool:connectionpool.py:870 Retrying (Retry(total=2, connect=None, read=None, redirect=None, status=None)) after connection broken by 'NewConnectionError('<urllib3.connection.HTTPConnection object at 0x0000028C1B3EF290>: Failed to establish a new connection: [WinError 10061] No connection could be made because the target machine actively refused it')': /session/26eb0c930d0b75b19fb93c9668e927fa/screenshot
WARNING  urllib3.connectionpool:connectionpool.py:870 Retrying (Retry(total=1, connect=None, read=None, redirect=None, status=None)) after connection broken by 'NewConnectionError('<urllib3.connection.HTTPConnection object at 0x0000028C1B3EF020>: Failed to establish a new connection: [WinError 10061] No connection could be made because the target machine actively refused it')': /session/26eb0c930d0b75b19fb93c9668e927fa/screenshot
WARNING  urllib3.connectionpool:connectionpool.py:870 Retrying (Retry(total=0, connect=None, read=None, redirect=None, status=None)) after connection broken by 'NewConnectionError('<urllib3.connection.HTTPConnection object at 0x0000028C1B3EEED0>: Failed to establish a new connection: [WinError 10061] No connection could be made because the target machine actively refused it')': /session/26eb0c930d0b75b19fb93c9668e927fa/screenshot
WARNING  urllib3.connectionpool:connectionpool.py:870 Retrying (Retry(total=2, connect=None, read=None, redirect=None, status=None)) after connection broken by 'NewConnectionError('<urllib3.connection.HTTPConnection object at 0x0000028C1B193320>: Failed to establish a new connection: [WinError 10061] No connection could be made because the target machine actively refused it')': /session/26eb0c930d0b75b19fb93c9668e927fa
WARNING  urllib3.connectionpool:connectionpool.py:870 Retrying (Retry(total=1, connect=None, read=None, redirect=None, status=None)) after connection broken by 'NewConnectionError('<urllib3.connection.HTTPConnection object at 0x0000028C1B3EF200>: Failed to establish a new connection: [WinError 10061] No connection could be made because the target machine actively refused it')': /session/26eb0c930d0b75b19fb93c9668e927fa
WARNING  urllib3.connectionpool:connectionpool.py:870 Retrying (Retry(total=0, connect=None, read=None, redirect=None, status=None)) after connection broken by 'NewConnectionError('<urllib3.connection.HTTPConnection object at 0x0000028C1B3EFF20>: Failed to establish a new connection: [WinError 10061] No connection could be made because the target machine actively refused it')': /session/26eb0c930d0b75b19fb93c9668e927fa